<?xml version="1.0"?>
<!-- Revolute-Revolute Manipulator -->
<robot name="ngws" xmlns:xacro="http://www.ros.org/wiki/xacro">

  <!-- Constants for robot dimensions -->
  <xacro:property name="PI" value="3.1415926535897931"/>
  <xacro:property name="mass" value="30" /> <!-- arbitrary value for mass -->
  <xacro:property name="width" value="0.6" /> <!-- Square dimensions (widthxwidth) of beams -->


  <!-- Import all Gazebo-customization elements, including Gazebo colors -->
  <xacro:include filename="$(find ngws_description)/urdf/gazebo/addon_v1.0.gazebo" />
  <!-- Import Rviz colors -->
  <xacro:include filename="$(find ngws_description)/urdf/materials/materials.xacro" />

  <xacro:include filename="$(find ngws_description)/urdf/mecanum_wheel/mecanum_wheel.xacro" />

  <!-- Used for fixing robot to Gazebo 'base_link' -->
<!--   <link name="world"/>

  <joint name="fixed" type="fixed">
    <parent link="world"/>
    <child link="link1"/>
  </joint> -->
    <!-- Used for fixing robot to Gazebo 'base_link' -->
  <link name="base_footprint"/>

  <joint name="base_joint" type="fixed">
    <origin xyz="0.0 0.0 0.03" rpy="0 0 0"/>
    <parent link="base_footprint"/>
    <child link="base_link"/>
  </joint>

  <!-- Base Link -->
  <link name="base_link">
    <collision>
      <origin xyz="0 0 0.15" rpy="0 0 0"/>
      <geometry>
                <!-- <box size="0.1 0.1 0.1" /> -->
        <mesh filename="package://ngws_description/meshes/cheshen.stl" scale="0.0008 0.0011 0.001"/>
      </geometry>
    </collision>

    <visual>
      <origin xyz="0 0 0.15" rpy="0 0 0"/>
      <geometry>
                <!-- <box size="0.1 0.1 0.1" /> -->
        <mesh filename="package://ngws_description/meshes/cheshen.stl" scale="0.0008 0.0011 0.001"/>
      </geometry>
      <material name="orange"/>
    </visual>

    <inertial>
      <origin xyz="0 0 0.1" rpy="0 0 0"/>
      <mass value="${mass}"/>
      <inertia
    ixx="${mass*0.083*2*width*width}" ixy="0.0" ixz="0.0"
    iyy="${mass*0.083*2*width*width}" iyz="0.0"
    izz="${mass*0.083*2*width*width}"/>
    </inertial>
  </link>

  <xacro:property name="mass_b" value="5" /> <!-- arbitrary value for mass -->

  <joint name="bridge1_joint" type="prismatic">
    <origin xyz="0 0 0" rpy="0 0 0"/>
    <parent link="base_link"/>
    <child link="bridge1_link"/>
    <axis xyz="0 0 1"/>
    <calibration rising="0.0"/>
    <dynamics damping="0.0" friction="0.0"/>
    <limit effort="0" velocity="0" lower="-0.03" upper="0.03"/>
  </joint>

  <link name="bridge1_link">
    <collision>
      <origin xyz="0.1 0.2 0.05" rpy="${PI*0.5} 0 0"/>
      <geometry>
        <cylinder radius="0.005" length="0.01" />
      </geometry>
    </collision>

    <collision>
      <origin xyz="0.1 -0.2 0.05" rpy="${PI*0.5} 0 0"/>
      <geometry>
        <cylinder radius="0.005" length="0.01" />
      </geometry>
    </collision>

    <visual>
      <origin xyz="0.1 0.2 0.05" rpy="${PI*0.5} 0 0"/>
      <geometry>
        <cylinder radius="0.005" length="0.01" />
      </geometry>
      <material name="orange"/>
    </visual>

    <visual>
      <origin xyz="0.1 -0.2 0.05" rpy="${PI*0.5} 0 0"/>
      <geometry>
        <cylinder radius="0.005" length="0.01" />
      </geometry>
      <material name="orange"/>
    </visual>

    <inertial>
      <origin xyz="0.1 0 0.05" rpy="${PI*0.5} 0 0"/>
      <mass value="${mass_b}"/>
      <inertia
    ixx="${mass_b*0.083*2*width*width}" ixy="0.0" ixz="0.0"
    iyy="${mass_b*0.083*2*width*width}" iyz="0.0"
    izz="${mass_b*0.083*2*width*width}"/>
    </inertial>

  </link>

  <joint name="bridge2_joint" type="prismatic">
    <origin xyz="0 0 0" rpy="0 0 0"/>
    <parent link="base_link"/>
    <child link="bridge2_link"/>
    <axis xyz="0 0 1"/>
    <calibration rising="0.0"/>
    <dynamics damping="0.0" friction="0.0"/>
    <limit effort="0" velocity="0" lower="-0.03" upper="0.03"/>
  </joint>

  <link name="bridge2_link">
    <collision>
      <origin xyz="-0.1 0.2 0.05" rpy="${PI*0.5} 0 0"/>
      <geometry>
        <cylinder radius="0.005" length="0.01" />
      </geometry>
    </collision>

    <collision>
      <origin xyz="-0.1 -0.2 0.05" rpy="${PI*0.5} 0 0"/>
      <geometry>
        <cylinder radius="0.005" length="0.01" />
      </geometry>
    </collision>

    <visual>
      <origin xyz="-0.1 0.2 0.05" rpy="${PI*0.5} 0 0"/>
      <geometry>
        <cylinder radius="0.005" length="0.01" />
      </geometry>
      <material name="orange"/>
    </visual>

    <visual>
      <origin xyz="-0.1 -0.2 0.05" rpy="${PI*0.5} 0 0"/>
      <geometry>
        <cylinder radius="0.005" length="0.01" />
      </geometry>
      <material name="orange"/>
    </visual>

    <inertial>
      <origin xyz="-0.1 0 0.05" rpy="${PI*0.5} 0 0"/>
      <mass value="${mass_b}"/>
      <inertia
    ixx="${mass_b*0.083*2*width*width}" ixy="0.0" ixz="0.0"
    iyy="${mass_b*0.083*2*width*width}" iyz="0.0"
    izz="${mass_b*0.083*2*width*width}"/>
    </inertial>

  </link>

  <joint name="bridge_m_joint" type="revolute">
    <origin xyz="0 0 0.065" rpy="0 0 0"/>
    <parent link="base_link"/>
    <child link="bridge_m_link"/>
    <axis xyz="0 1 0"/>
    <calibration rising="0.0"/>
    <dynamics damping="0.0" friction="0.0"/>
    <limit effort="0" velocity="0" lower="-0.2" upper="0.2"/>
  </joint>

  <link name="bridge_m_link">
    <collision>
      <origin xyz="0 0.2 0" rpy="${PI*0.5} 0 ${PI*0.5}"/>
      <geometry>
        <box size="0.01 0.01 0.25"/>
      </geometry>
    </collision>

    <collision>
      <origin xyz="0 -0.2 0" rpy="${PI*0.5} 0 ${PI*0.5}"/>
      <geometry>
        <box size="0.01 0.01 0.25"/>
      </geometry>
    </collision>

    <visual>
      <origin xyz="0 0.2 0" rpy="${PI*0.5} 0 ${PI*0.5}"/>
      <geometry>
        <box size="0.01 0.01 0.25"/>
      </geometry>
      <material name="orange"/>
    </visual>

    <visual>
      <origin xyz="0 -0.2 0" rpy="${PI*0.5} 0 ${PI*0.5}"/>
      <geometry>
        <box size="0.01 0.01 0.25"/>
      </geometry>
      <material name="orange"/>
    </visual>

    <inertial>
      <origin xyz="0 0 0" rpy="${PI*0.5} 0 ${PI*0.5}"/>
      <mass value="${mass_b}"/>
      <inertia
    ixx="${mass_b*0.083*2*width*width}" ixy="0.0" ixz="0.0"
    iyy="${mass_b*0.083*2*width*width}" iyz="0.0"
    izz="${mass_b*0.083*2*width*width}"/>
    </inertial>

  </link>

  <!-- subwheel -->
    <xacro:property name="wheel_mass" value="2"/>
    <xacro:property name="main_radius" value="0.041"/>
    <xacro:property name="caster" value="${PI*0.25}"/>

    <xacro:property name="main_mesh_file" value="package://ngws_description/meshes/mecanum_wheel.stl"/>
    <xacro:property name="main_mesh_file_rev" value="package://ngws_description/meshes/mecanum_wheel_r.stl"/>
    <xacro:property name="sub_mesh_file" value="package://ngws_description/meshes/mecanum_miniwheel_small.stl"/>

    <xacro:property name="wheel_T_offset" value="${PI/100*0}"/>

  <!-- FR -->
  <xacro:mecanum_wheel_macro
    name="wheel_FR"
    parent_link="bridge2_link"
    joint_type="continuous"
    mass="${wheel_mass}"
    has_10_subwheel="true"
    main_radius="${main_radius}"
    caster="${caster}"
    main_mesh_file="${main_mesh_file_rev}"
    sub_mesh_file="${sub_mesh_file}"
    mesh_scale="0.001"
    x="0.3"
    y="-0.3"
    z="0.02"
    R="${wheel_T_offset}"
    P="0.0"
    Y="${PI/2}"
    >
  </xacro:mecanum_wheel_macro>

<!-- FL -->

  <xacro:mecanum_wheel_macro
    name="wheel_FL"
    parent_link="bridge1_link"
    joint_type="continuous"
    mass="${wheel_mass}"
    has_10_subwheel="true"
    main_radius="${main_radius}"
    caster="-${caster}"
    main_mesh_file="${main_mesh_file}"
    sub_mesh_file="${sub_mesh_file}"
    mesh_scale="0.001"
    x="0.3"
    y="0.3"
    z="0.02"
    R="${wheel_T_offset}"
    P="0.0"
    Y="${PI/2}"
    >
  </xacro:mecanum_wheel_macro>
  
<!-- BR -->
  <xacro:mecanum_wheel_macro
    name="wheel_BR"
    parent_link="bridge1_link"
    joint_type="continuous"
    mass="${wheel_mass}"
    has_10_subwheel="true"
    main_radius="${main_radius}"
    caster="-${caster}"
    main_mesh_file="${main_mesh_file}"
    sub_mesh_file="${sub_mesh_file}"
    mesh_scale="0.001"
    x="-0.3"
    y="-0.3"
    z="0.02"
    R="${wheel_T_offset}"
    P="0.0"
    Y="${PI/2}"
    >
  </xacro:mecanum_wheel_macro>


<!-- BL -->
  <xacro:mecanum_wheel_macro
    name="wheel_BL"
    parent_link="bridge2_link"
    joint_type="continuous"
    mass="${wheel_mass}"
    has_10_subwheel="true"
    main_radius="${main_radius}"
    caster="${caster}"
    main_mesh_file="${main_mesh_file_rev}"
    sub_mesh_file="${sub_mesh_file}"
    mesh_scale="0.001"
    x="-0.3"
    y="0.3"
    z="0.02"
    R="${wheel_T_offset}"
    P="0.0"
    Y="${PI/2}"
    >
  </xacro:mecanum_wheel_macro>



  <!-- Wheel FR -->
  <!-- <joint name="wheel_FR_joint" type="continuous">
    <axis xyz="0 0 -1" />
    <origin xyz="0.2 -0.4 0.05" rpy="${PI/2.0} 0 0"/>
    <parent link="base_link"/>
    <child link="wheel_FR_link"/>
  </joint>

  <link name="wheel_FR_link">
    <collision>
      <origin xyz="0 0 0" rpy="0 0 0"/>
      <geometry>
        <mesh filename="package://ngws_description/meshes/mecanum_wheel.stl" scale="0.001 0.001 0.001"/>
      </geometry>
    </collision>

    <visual>
      <origin xyz="0 0 0" rpy="0 0 0"/>
      <geometry>
        <mesh filename="package://ngws_description/meshes/mecanum_wheel.stl" scale="0.001 0.001 0.001"/>
      </geometry>
      <material name="red"/>
    </visual>

    <inertial>
      <mass value="2" />
      <origin xyz="0 0 0" rpy="0 0 0"/>
        <inertia
        ixx="0.005" ixy="0.0" ixz="0.0"
        iyy="0.005" iyz="0.0"
        izz="0.009"/>
    </inertial>
  </link> -->












  <!-- Wheel FL -->
  <!-- <joint name="wheel_FL_joint" type="continuous">
    <axis xyz="0 0 -1" />
    <origin xyz="0.2 0.2 0.05" rpy="${PI/2.0} 0 0"/>
    <parent link="base_link"/>
    <child link="wheel_FL_link"/>
  </joint>


  <link name="wheel_FL_link">
    <collision>
      <origin xyz="0 0 0" rpy="0 0 0"/>
      <geometry>
        <mesh filename="package://ngws_description/meshes/mecanum_wheel.stl" scale="0.001 0.001 0.001"/>
      </geometry>
    </collision>

    <visual>
      <origin xyz="0 0 0" rpy="0 0 0"/>
      <geometry>
        <mesh filename="package://ngws_description/meshes/mecanum_wheel.stl" scale="0.001 0.001 0.001"/>
      </geometry>
      <material name="black"/>
    </visual>

    <inertial>
      <mass value="2" />
      <origin xyz="0 0 0" rpy="0 0 0"/>
        <inertia
        ixx="0.005" ixy="0.0" ixz="0.0"
        iyy="0.005" iyz="0.0"
        izz="0.009"/>
    </inertial>
  </link> -->

<!-- Wheel BR -->
 <!--  <joint name="wheel_BR_joint" type="continuous">
    <axis xyz="0 0 -1" />
    <origin xyz="-0.2 -0.2 0.05" rpy="${PI/2.0} 0 0"/>
    <parent link="base_link"/>
    <child link="wheel_BR_link"/>
  </joint>

  
  <link name="wheel_BR_link">
    <collision>
      <origin xyz="0 0 0" rpy="0 0 0"/>
      <geometry>
        <mesh filename="package://ngws_description/meshes/mecanum_wheel.stl" scale="0.001 0.001 0.001"/>
      </geometry>
    </collision>

    <visual>
      <origin xyz="0 0 0" rpy="0 0 0"/>
      <geometry>
        <mesh filename="package://ngws_description/meshes/mecanum_wheel.stl" scale="0.001 0.001 0.001"/>
      </geometry>
      <material name="black"/>
    </visual>

    <inertial>
      <mass value="2" />
      <origin xyz="0 0 0" rpy="0 0 0"/>
        <inertia
        ixx="0.005" ixy="0.0" ixz="0.0"
        iyy="0.005" iyz="0.0"
        izz="0.009"/>
    </inertial>
  </link> -->

<!-- Wheel BL -->
  <!-- <joint name="wheel_BL_joint" type="continuous">
    <axis xyz="0 0 -1" />
    <origin xyz="-0.2 0.2 0.05" rpy="${PI/2.0} 0 0"/>
    <parent link="base_link"/>
    <child link="wheel_BL_link"/>
  </joint>

  
  <link name="wheel_BL_link">
    <collision>
      <origin xyz="0 0 0" rpy="0 0 0"/>
      <geometry>
        <mesh filename="package://ngws_description/meshes/mecanum_wheel.stl" scale="0.001 0.001 0.001"/>
      </geometry>
    </collision>

    <visual>
      <origin xyz="0 0 0" rpy="0 0 0"/>
      <geometry>
        <mesh filename="package://ngws_description/meshes/mecanum_wheel.stl" scale="0.001 0.001 0.001"/>
      </geometry>
      <material name="black"/>
    </visual>

    <inertial>
      <mass value="2" />
      <origin xyz="0 0 0" rpy="0 0 0"/>
        <inertia
        ixx="0.005" ixy="0.0" ixz="0.0"
        iyy="0.005" iyz="0.0"
        izz="0.009"/>
    </inertial>
  </link> -->






  <!-- Laser -->

 <!--  <joint name="laser_joint" type="fixed">
    <axis xyz="0 1 0" />
    <origin xyz="0.0 0 0.35" rpy="0 0 0"/>
    <parent link="base_link"/>
    <child link="laser_link"/>
  </joint>


  <link name="laser_link">
    <collision>
      <origin xyz="0 0 0" rpy="0 0 0"/>
      <geometry>
  <box size="0.1 0.1 0.1"/>
      </geometry>
    </collision>

    <visual>
      <origin xyz="0 0 0" rpy="0 0 0"/>
      <geometry>
        <mesh filename="package://ngws_description/meshes/hokuyo.dae"/>
      </geometry>
    </visual>

    <inertial>
      <mass value="1e-5" />
      <origin xyz="0 0 0" rpy="0 0 0"/>
      <inertia ixx="1e-6" ixy="0" ixz="0" iyy="1e-6" iyz="0" izz="1e-6" />
    </inertial>
  </link> -->


  <joint name="camera_joint" type="fixed">
    <axis xyz="0 1 0" />
    <origin xyz="0 0 0.2" rpy="0 ${PI/2.0} 0"/>
    <parent link="base_link"/>
    <child link="camera_link"/>
  </joint>

  <!-- Camera -->
  <link name="camera_link">
    <collision>
      <origin xyz="0 0 0" rpy="0 0 0"/>
      <geometry>
  <box size="0.06 0.06 0.06 "/>
      </geometry>
    </collision>

    <visual>
      <origin xyz="0 0 0" rpy="0 0 0"/>
      <geometry>
  <box size="0.06 0.06 0.06"/>
      </geometry>
      <material name="red"/>
    </visual>

    <inertial>
      <mass value="1e-5" />
      <origin xyz="0 0 0" rpy="0 0 0"/>
      <inertia ixx="1e-6" ixy="0" ixz="0" iyy="1e-6" iyz="0" izz="1e-6" />
    </inertial>
  </link>


  <transmission name="tran1">
    <type>transmission_interface/SimpleTransmission</type>
    <joint name="wheel_FR_joint">
      <hardwareInterface>VelocityJointInterface</hardwareInterface>
    </joint>
    <actuator name="motor1">
      <hardwareInterface>VelocityJointInterface</hardwareInterface>
      <mechanicalReduction>1</mechanicalReduction>
    </actuator>
  </transmission>

  <transmission name="tran2">
    <type>transmission_interface/SimpleTransmission</type>
    <joint name="wheel_FL_joint">
      <hardwareInterface>VelocityJointInterface</hardwareInterface>
    </joint>
    <actuator name="motor2">
      <hardwareInterface>VelocityJointInterface</hardwareInterface>
      <mechanicalReduction>1</mechanicalReduction>
    </actuator>
  </transmission>

  <transmission name="tran3">
    <type>transmission_interface/SimpleTransmission</type>
    <joint name="wheel_BR_joint">
      <hardwareInterface>VelocityJointInterface</hardwareInterface>
    </joint>
    <actuator name="motor3">
      <hardwareInterface>VelocityJointInterface</hardwareInterface>
      <mechanicalReduction>1</mechanicalReduction>
    </actuator>
  </transmission>

  <transmission name="tran4">
    <type>transmission_interface/SimpleTransmission</type>
    <joint name="wheel_BL_joint">
      <hardwareInterface>VelocityJointInterface</hardwareInterface>
    </joint>
    <actuator name="motor4">
      <hardwareInterface>VelocityJointInterface</hardwareInterface>
      <mechanicalReduction>1</mechanicalReduction>
    </actuator>
  </transmission>



</robot>
